Workbook
Name _____________R: #REF!
Name ____________R: #REF!
Name ___________R: #REF!
Name __________R: #REF!
Name _________R: #REF!
Name ________R: #REF!
Name _______R: #REF!
Name ______R: #REF!
Name _____R: #REF!
Name ____R: #REF!
Name ___R: #REF!
Name __R: #REF!
Name _R: #REF!
Name a: #REF!
Name Bedrock: #REF!
Name CHECK: #REF!
Name Cohesive: #REF!
Name Colour: [1]XCodes!$L$2:$L$11
Name coords: '[2]Field Drill Site Check'!$E$2:$G$31
Name CSCD: '[3]DATOS LG'!$B$4:$B$11
Name Cw: #REF!
Name D: #REF!
Name Density_Cohesive: '[4]Hole ID'!$I$47:$I$52
Name Density_Granular: '[4]Hole ID'!$H$47:$H$51
Name DFGDF: #REF!
Name Dilatancy: '[4]Hole ID'!$P$47:$P$49
Name EF: '[5]DATOS LG'!$E$4:$E$10
Name FE: #REF!
Name FTRT: #REF!
Name Geologist_Name: [6]XCodes!$O$2:$O$58
Name GGGG: #REF!
Name Grain_Size: [1]XCodes!$R$2:$R$4
Name Granular: #REF!
Name henry: #REF!
Name INTEMPERISMO: '[7]DATOS LG'!$E$4:$E$10
Name L: #REF!
Name Lithology: [1]XCodes!$C$2:$C$29
Name Lithologys: [1]XCodes!$A$2:$A$28
Name LITO_RMR: #REF!
Name LITOLOGIA: '[7]DATOS LG'!$I$4:$I$33
Name Litology_Lookup: [8]Litología_Lookup!#REF!
Name LMT_M: '[7]LG EST.'!#REF!
Name longitude: #REF!
Name Magnetite_Style: [1]XCodes!$U$2:$U$5
Name n: #REF!
Name Non_Plastic: '[4]Hole ID'!$O$46
Name Plasticity: '[4]Hole ID'!$N$47:$N$50
Name q: #REF!
Name RESISTENCIA: '[7]DATOS LG'!$B$4:$B$11
Name S: #REF!
Name Structure: [1]XCodes!$AV$2:$AV$10
Name SW: '[9]DATOS LG'!$B$4:$B$11
Name Texture: [1]XCodes!$AY$2:$AY$9
Name th: '[2]Field Drill Site Check'!$G$2:$H$31
Name w: #REF!

Sheet ventana
AY3: =A4 -> TD1
A4: TD1 | D4: UBICACIÓN | F4: Cota | I4: LONGITUD | L4: ORIENTACION | O4: LITO-3 | T4: SECTOR | AJ4: Fecha:
A5: INI | I5: LARGO | K5: =(((B6-B5)^2)+((D6-D5)^2)+((F6-F5)^2))^(1/2) -> 0 | L5: Dip_talud | O5: ALT | T5: FASE | W5: JT-JV | AJ5: Condicion de Agua | AK5: Condicion de aglorua Valor | AL5: Resistencia Estimada | AM5: Resistencia Estimada(Valor) | AN5: Condición de la SUP(GSI) | AO5: Estructura(GSI) | AP5: GSI (Visual) | AQ5: Control Estructural | AR5: Efectos de la Voladura | AS5: RQD (valor) | AT5: RQD (%) | AU5: Frecuencia de Fracturamiento x m | AV5: Tamaño de Bloque m3 | AW5: Espaciamiento prom | AX5: Espaciamiento Valor | AY5: Valor ConDisc | AZ5: RMR | BA5: ( UCS ) (Mpa) | BB5: is50 (Mpa)
A6: FIN | I6: ALTURA | L6: DipDir_Talud | N6: =(N8)+90 -> #DIV/0! | O6: INT | T6: NIVEL
J7: =IF(B6-B5>0,1,0) -> 0 | K7: =IF(AND(D6-B6>0,D5-B5=0),1,IF(AND(D6-B6<0,D5-B5=0),0,"")) | L7: Dip_hole | N7: =DEGREES(ASIN((F5-F6)/K5)) -> #DIV/0! | O7: Lito-Model | T7: Sect. GEOT.
L8: Az_hole | N8: =IF(K7=1,0,IF(K7=0,180,IF(J7=1,DEGREES(_xlfn.ACOT((D6-D5)/(B6-B5))),180+DEGREES(_xlfn.ACOT((D6-D5)/(B6-B5)))))) -> #DIV/0! | O8: Mapeador:
W9: Condicion de las Discontinuidades (JC 1976) | AC9: Condicion de las Discontinuidades (JC 1989)
A10: ID | B10: Distancia (m) | C10: Tipo de Estructura | D10: Dip | E10: Dip Dir | F10: N de Estructuras | G10: Abertura(mm) | H10: Espesor (mm) | I10: Continuidad (m) | J10: Espaciamiento (m) | K10: N de Extremos Visibles | L10: TERMINACION | M10: Tipo de Relleno 1 | N10: Tipo de Relleno 2 | O10: Valor de relleno 1 | P10: Valor de relleno 2 | Q10: Valor de relleno 1 | R10: Valor de relleno 2 | S10: JRC | T10: Rugosidad de Estructura | U10: Forma de Estructura | V10: Alteracion | W10: Valor de Alteracion | X10: Valor de relleno | Y10: Continuidad | Z10: Abertura | AA10: Rugosidad | AB10: Valor | AC10: Valor de Alteracion | AD10: Valor de relleno | AE10: Continuidad | AF10: Abertura | AG10: Rugosidad | AH10: Valor
AI11: 76 | AK11: =VLOOKUP(AJ11,RMR!$B$84:$D$88,2,FALSE) -> #N/A | AM11: =VLOOKUP(AL11,RMR!$A$5:$D$11,4,FALSE) -> #N/A | AS11: =VLOOKUP(AT11,RMR!$A$15:$D$19,4,TRUE) -> #DIV/0! | AT11: =115-3.3*N31 -> #DIV/0! | AU11: =(1/AW11)+1 -> #DIV/0! | AV11: =(J29+J30+J31)/3 -> #DIV/0! | AW11: =(J15*F15+J16*F16+J17*F17+J18*F18+J19*F19+J20*F20+J21*F21+J22*F22+J23*F23)/SUM(F15:F23) -> #DIV/0! | AX11: =VLOOKUP(AW11,RMR!$D$24:$F$28,3,TRUE) -> #DIV/0! | AY11: =(AB15*F15+AB16*F16+AB17*F17+AB18*F18+AB19*F19+AB20*F20+AB21*F21+AB22*F22+AB23*F23+AB24*F24+AB25*F25+AB26*F26+AB27*F27+AB28*F28)/SUM(F15:F28) -> #VALUE! | AZ11: =SUM(AY11,AX11,AS11,AM11,AK11) -> #VALUE!
AI12: 89 | AK12: =VLOOKUP(AJ12,RMR!$B$84:$D$88,3,FALSE) -> #N/A | AM12: =VLOOKUP(AL12,RMR!$A$5:$D$11,3,FALSE) -> #N/A | AS12: =IF(AT12<0,"Error",IF(AND(AT12>=0,AT12<=100),((-0.000006*AT12^3)+0.0015*AT12^2+0.0806*AT12+3.0282),IF(AT12>100,"Error","Revisar"))) -> #DIV/0! | AT12: =115-3.3*N31 -> #DIV/0! | AU12: =AU11 -> #DIV/0! | AV12: =AV11 -> #DIV/0! | AW12: =AW11 -> #DIV/0! | AX12: =VLOOKUP(AW12,RMR!$A$24:$C$28,3,TRUE) -> #DIV/0! | AY12: =(AH15*F15+AH16*F16+AH17*F17+AH18*F18+AH19*F19+AH20*F20+AH21*F21+AH22*F22+AH23*F23+AH24*F24+AH25*F25+AH26*F26+AH27*F27+AH28*F28)/SUM(F15:F28) -> #N/A | AZ12: =SUM(AY12,AX12,AS12,AM12,AK12) -> #N/A
BW14: Codigo(espesor) | BX14: Codigo(relleno 1) | BY14: Codigo(relleno 1) | BZ14: Codigo(relleno 2) | CA14: Codigo(relleno 2)
O15: =IF(BY15="","",VLOOKUP(BY15,RMR!$N$77:$Q$81,4,TRUE)) | P15: =IF(CA15="","",VLOOKUP(CA15,RMR!$N$77:$Q$81,4,TRUE)) | Q15: =IF(BY15="","",VLOOKUP(BY15,RMR!$N$77:$Q$81,3,TRUE)) | R15: =IF(CA15="","",VLOOKUP(CA15,RMR!$N$77:$Q$81,3,TRUE)) | W15: =VLOOKUP(V15,RMR!$A$40:$C$45,3,FALSE) -> #N/A | X15: =IF(O15="","error",MIN(O15:P15)) -> error | Y15: =VLOOKUP(I15,RMR!$A$31:$D$35,4,TRUE) -> #N/A | Z15: =IF(G15="","error",VLOOKUP(G15,RMR!$B$51:$E$55,4,TRUE)) -> error | AA15: =VLOOKUP(T15,RMR!$A$59:$C$67,3,TRUE) -> #N/A | AB15: =SUM(X15+Y15+Z15+AA15+W15) -> #VALUE! | AC15: =VLOOKUP(V15,RMR!$A$40:$C$45,2,FALSE) -> #N/A | AD15: =IF(Q15="","error",MIN(Q15:R15)) -> error | AE15: =VLOOKUP(I15,RMR!$A$31:$D$35,3,TRUE) -> #N/A | AF15: =IF(G15="","error",VLOOKUP(G15,RMR!$B$51:$E$55,3,TRUE)) -> error | AG15: =VLOOKUP(T15,RMR!$A$59:$C$67,2,TRUE) -> #N/A | AH15: =SUM(AC15+AD15+AE15+AF15+AG15) -> #N/A | AI15: =(5/J15)/3 -> #DIV/0! | BW15: =IF(H15="","error",VLOOKUP(H15,RMR!$N$73:$P$74,3,TRUE)) -> error | BX15: =IF(OR(M15=-1,M15=""),"",VLOOKUP(M15,RMR!$A$72:$B$79,2,FALSE)) | BY15: =IF(BX15=3,5,IF(BX15="","",IF(AND(BX15=1,BW15=1),1,IF(AND(BX15=1,BW15=2),2,IF(AND(BX15=2,BW15=1),3,IF(AND(BX15=2,BW15=2),4,"error")))))) | BZ15: =IF(OR(N15=-1,N15=""),"",VLOOKUP(N15,RMR!$A$73:$B$79,2,FALSE)) | CA15: =IF(BZ15="","",IF(AND(BZ15=1,BW15=1),1,IF(AND(BZ15=1,BW15=2),2,IF(AND(BZ15=2,BW15=1),3,IF(AND(BZ15=2,BW15=2),4,"error")))))
O16: =IF(BY16="","",VLOOKUP(BY16,RMR!$N$77:$Q$81,4,TRUE)) | P16: =IF(CA16="","",VLOOKUP(CA16,RMR!$N$77:$Q$81,4,TRUE)) | Q16: =IF(BY16="","",VLOOKUP(BY16,RMR!$N$77:$Q$81,3,TRUE)) | R16: =IF(CA16="","",VLOOKUP(CA16,RMR!$N$77:$Q$81,3,TRUE)) | BW16: =IF(H16="","error",VLOOKUP(H16,RMR!$N$73:$P$74,3,TRUE)) -> error | BX16: =IF(OR(M16=-1,M16=""),"",VLOOKUP(M16,RMR!$A$72:$B$79,2,FALSE)) | BY16: =IF(BX16=3,5,IF(BX16="","",IF(AND(BX16=1,BW16=1),1,IF(AND(BX16=1,BW16=2),2,IF(AND(BX16=2,BW16=1),3,IF(AND(BX16=2,BW16=2),4,"error")))))) | BZ16: =IF(OR(N16=-1,N16=""),"",VLOOKUP(N16,RMR!$A$73:$B$79,2,FALSE)) | CA16: =IF(BZ16="","",IF(AND(BZ16=1,BW16=1),1,IF(AND(BZ16=1,BW16=2),2,IF(AND(BZ16=2,BW16=1),3,IF(AND(BZ16=2,BW16=2),4,"error")))))
O17: =IF(BY17="","",VLOOKUP(BY17,RMR!$N$77:$Q$81,4,TRUE)) | P17: =IF(CA17="","",VLOOKUP(CA17,RMR!$N$77:$Q$81,4,TRUE)) | Q17: =IF(BY17="","",VLOOKUP(BY17,RMR!$N$77:$Q$81,3,TRUE)) | R17: =IF(CA17="","",VLOOKUP(CA17,RMR!$N$77:$Q$81,3,TRUE)) | BW17: =IF(H17="","error",VLOOKUP(H17,RMR!$N$73:$P$74,3,TRUE)) -> error | BX17: =IF(OR(M17=-1,M17=""),"",VLOOKUP(M17,RMR!$A$72:$B$79,2,FALSE)) | BY17: =IF(BX17=3,5,IF(BX17="","",IF(AND(BX17=1,BW17=1),1,IF(AND(BX17=1,BW17=2),2,IF(AND(BX17=2,BW17=1),3,IF(AND(BX17=2,BW17=2),4,"error")))))) | BZ17: =IF(OR(N17=-1,N17=""),"",VLOOKUP(N17,RMR!$A$73:$B$79,2,FALSE)) | CA17: =IF(BZ17="","",IF(AND(BZ17=1,BW17=1),1,IF(AND(BZ17=1,BW17=2),2,IF(AND(BZ17=2,BW17=1),3,IF(AND(BZ17=2,BW17=2),4,"error")))))
O18: =IF(BY18="","",VLOOKUP(BY18,RMR!$N$77:$Q$81,4,TRUE)) | P18: =IF(CA18="","",VLOOKUP(CA18,RMR!$N$77:$Q$81,4,TRUE)) | Q18: =IF(BY18="","",VLOOKUP(BY18,RMR!$N$77:$Q$81,3,TRUE)) | R18: =IF(CA18="","",VLOOKUP(CA18,RMR!$N$77:$Q$81,3,TRUE)) | BW18: =IF(H18="","error",VLOOKUP(H18,RMR!$N$73:$P$74,3,TRUE)) -> error | BX18: =IF(OR(M18=-1,M18=""),"",VLOOKUP(M18,RMR!$A$72:$B$79,2,FALSE)) | BY18: =IF(BX18=3,5,IF(BX18="","",IF(AND(BX18=1,BW18=1),1,IF(AND(BX18=1,BW18=2),2,IF(AND(BX18=2,BW18=1),3,IF(AND(BX18=2,BW18=2),4,"error")))))) | BZ18: =IF(OR(N18=-1,N18=""),"",VLOOKUP(N18,RMR!$A$73:$B$79,2,FALSE)) | CA18: =IF(BZ18="","",IF(AND(BZ18=1,BW18=1),1,IF(AND(BZ18=1,BW18=2),2,IF(AND(BZ18=2,BW18=1),3,IF(AND(BZ18=2,BW18=2),4,"error")))))
O19: =IF(BY19="","",VLOOKUP(BY19,RMR!$N$77:$Q$81,4,TRUE)) | P19: =IF(CA19="","",VLOOKUP(CA19,RMR!$N$77:$Q$81,4,TRUE)) | Q19: =IF(BY19="","",VLOOKUP(BY19,RMR!$N$77:$Q$81,3,TRUE)) | R19: =IF(CA19="","",VLOOKUP(CA19,RMR!$N$76:$Q$79,3,TRUE)) | BW19: =IF(H19="","error",VLOOKUP(H19,RMR!$N$73:$P$74,3,TRUE)) -> error | BX19: =IF(OR(M19=-1,M19=""),"",VLOOKUP(M19,RMR!$A$72:$B$79,2,FALSE)) | BY19: =IF(BX19=3,5,IF(BX19="","",IF(AND(BX19=1,BW19=1),1,IF(AND(BX19=1,BW19=2),2,IF(AND(BX19=2,BW19=1),3,IF(AND(BX19=2,BW19=2),4,"error")))))) | BZ19: =IF(OR(N19=-1,N19=""),"",VLOOKUP(N19,RMR!$A$73:$B$79,2,FALSE)) | CA19: =IF(BZ19="","",IF(AND(BZ19=1,BW19=1),1,IF(AND(BZ19=1,BW19=2),2,IF(AND(BZ19=2,BW19=1),3,IF(AND(BZ19=2,BW19=2),4,"error")))))
O20: =IF(BY20="","",VLOOKUP(BY20,RMR!$N$77:$Q$81,4,TRUE)) | P20: =IF(CA20="","",VLOOKUP(CA20,RMR!$N$77:$Q$81,4,TRUE)) | Q20: =IF(BY20="","",VLOOKUP(BY20,RMR!$N$77:$Q$81,3,TRUE)) | R20: =IF(CA20="","",VLOOKUP(CA20,RMR!$N$76:$Q$79,3,TRUE)) | BD20: Comentarios: | BW20: =IF(H20="","error",VLOOKUP(H20,RMR!$N$73:$P$74,3,TRUE)) -> error | BX20: =IF(OR(M20=-1,M20=""),"",VLOOKUP(M20,RMR!$A$72:$B$79,2,FALSE)) | BY20: =IF(BX20=3,5,IF(BX20="","",IF(AND(BX20=1,BW20=1),1,IF(AND(BX20=1,BW20=2),2,IF(AND(BX20=2,BW20=1),3,IF(AND(BX20=2,BW20=2),4,"error")))))) | BZ20: =IF(OR(N20=-1,N20=""),"",VLOOKUP(N20,RMR!$A$73:$B$79,2,FALSE)) | CA20: =IF(BZ20="","",IF(AND(BZ20=1,BW20=1),1,IF(AND(BZ20=1,BW20=2),2,IF(AND(BZ20=2,BW20=1),3,IF(AND(BZ20=2,BW20=2),4,"error")))))
O21: =IF(BY21="","",VLOOKUP(BY21,RMR!$N$77:$Q$81,4,TRUE)) | P21: =IF(CA21="","",VLOOKUP(CA21,RMR!$N$77:$Q$81,4,TRUE)) | Q21: =IF(BY21="","",VLOOKUP(BY21,RMR!$N$77:$Q$81,3,TRUE)) | R21: =IF(CA21="","",VLOOKUP(CA21,RMR!$N$76:$Q$79,3,TRUE)) | BW21: =IF(H21="","error",VLOOKUP(H21,RMR!$N$73:$P$74,3,TRUE)) -> error | BX21: =IF(OR(M21=-1,M21=""),"",VLOOKUP(M21,RMR!$A$72:$B$79,2,FALSE)) | BY21: =IF(BX21=3,5,IF(BX21="","",IF(AND(BX21=1,BW21=1),1,IF(AND(BX21=1,BW21=2),2,IF(AND(BX21=2,BW21=1),3,IF(AND(BX21=2,BW21=2),4,"error")))))) | BZ21: =IF(OR(N21=-1,N21=""),"",VLOOKUP(N21,RMR!$A$73:$B$79,2,FALSE)) | CA21: =IF(BZ21="","",IF(AND(BZ21=1,BW21=1),1,IF(AND(BZ21=1,BW21=2),2,IF(AND(BZ21=2,BW21=1),3,IF(AND(BZ21=2,BW21=2),4,"error")))))
O22: =IF(BY22="","",VLOOKUP(BY22,RMR!$N$77:$Q$81,4,TRUE)) | P22: =IF(CA22="","",VLOOKUP(CA22,RMR!$N$77:$Q$81,4,TRUE)) | Q22: =IF(BY22="","",VLOOKUP(BY22,RMR!$N$77:$Q$81,3,TRUE)) | R22: =IF(CA22="","",VLOOKUP(CA22,RMR!$N$76:$Q$79,3,TRUE)) | BW22: =IF(H22="","error",VLOOKUP(H22,RMR!$N$73:$P$74,3,TRUE)) -> error | BX22: =IF(OR(M22=-1,M22=""),"",VLOOKUP(M22,RMR!$A$72:$B$79,2,FALSE)) | BY22: =IF(BX22=3,5,IF(BX22="","",IF(AND(BX22=1,BW22=1),1,IF(AND(BX22=1,BW22=2),2,IF(AND(BX22=2,BW22=1),3,IF(AND(BX22=2,BW22=2),4,"error")))))) | BZ22: =IF(OR(N22=-1,N22=""),"",VLOOKUP(N22,RMR!$A$73:$B$79,2,FALSE)) | CA22: =IF(BZ22="","",IF(AND(BZ22=1,BW22=1),1,IF(AND(BZ22=1,BW22=2),2,IF(AND(BZ22=2,BW22=1),3,IF(AND(BZ22=2,BW22=2),4,"error")))))
O23: =IF(BY23="","",VLOOKUP(BY23,RMR!$N$77:$Q$81,4,TRUE)) | P23: =IF(CA23="","",VLOOKUP(CA23,RMR!$N$77:$Q$81,4,TRUE)) | Q23: =IF(BY23="","",VLOOKUP(BY23,RMR!$N$77:$Q$81,3,TRUE)) | R23: =IF(CA23="","",VLOOKUP(CA23,RMR!$N$76:$Q$79,3,TRUE)) | BW23: =IF(H23="","error",VLOOKUP(H23,RMR!$N$73:$P$74,3,TRUE)) -> error | BX23: =IF(OR(M23=-1,M23=""),"",VLOOKUP(M23,RMR!$A$72:$B$79,2,FALSE)) | BY23: =IF(BX23=3,5,IF(BX23="","",IF(AND(BX23=1,BW23=1),1,IF(AND(BX23=1,BW23=2),2,IF(AND(BX23=2,BW23=1),3,IF(AND(BX23=2,BW23=2),4,"error")))))) | BZ23: =IF(OR(N23=-1,N23=""),"",VLOOKUP(N23,RMR!$A$73:$B$79,2,FALSE)) | CA23: =IF(BZ23="","",IF(AND(BZ23=1,BW23=1),1,IF(AND(BZ23=1,BW23=2),2,IF(AND(BZ23=2,BW23=1),3,IF(AND(BZ23=2,BW23=2),4,"error")))))
O24: =IF(BY24="","",VLOOKUP(BY24,RMR!$N$77:$Q$81,4,TRUE)) | P24: =IF(CA24="","",VLOOKUP(CA24,RMR!$N$77:$Q$81,4,TRUE)) | Q24: =IF(BY24="","",VLOOKUP(BY24,RMR!$N$77:$Q$81,3,TRUE)) | R24: =IF(CA24="","",VLOOKUP(CA24,RMR!$N$76:$Q$79,3,TRUE)) | BW24: =IF(H24="","error",VLOOKUP(H24,RMR!$N$73:$P$74,3,TRUE)) -> error | BX24: =IF(OR(M24=-1,M24=""),"",VLOOKUP(M24,RMR!$A$72:$B$79,2,FALSE)) | BY24: =IF(BX24=3,5,IF(BX24="","",IF(AND(BX24=1,BW24=1),1,IF(AND(BX24=1,BW24=2),2,IF(AND(BX24=2,BW24=1),3,IF(AND(BX24=2,BW24=2),4,"error")))))) | BZ24: =IF(OR(N24=-1,N24=""),"",VLOOKUP(N24,RMR!$A$73:$B$79,2,FALSE)) | CA24: =IF(BZ24="","",IF(AND(BZ24=1,BW24=1),1,IF(AND(BZ24=1,BW24=2),2,IF(AND(BZ24=2,BW24=1),3,IF(AND(BZ24=2,BW24=2),4,"error")))))
O25: =IF(BY25="","",VLOOKUP(BY25,RMR!$N$77:$Q$81,4,TRUE)) | P25: =IF(CA25="","",VLOOKUP(CA25,RMR!$N$77:$Q$81,4,TRUE)) | Q25: =IF(BY25="","",VLOOKUP(BY25,RMR!$N$77:$Q$81,3,TRUE)) | R25: =IF(CA25="","",VLOOKUP(CA25,RMR!$N$76:$Q$79,3,TRUE)) | BW25: =IF(H25="","error",VLOOKUP(H25,RMR!$N$73:$P$74,3,TRUE)) -> error | BX25: =IF(OR(M25=-1,M25=""),"",VLOOKUP(M25,RMR!$A$72:$B$79,2,FALSE)) | BY25: =IF(BX25=3,5,IF(BX25="","",IF(AND(BX25=1,BW25=1),1,IF(AND(BX25=1,BW25=2),2,IF(AND(BX25=2,BW25=1),3,IF(AND(BX25=2,BW25=2),4,"error")))))) | BZ25: =IF(OR(N25=-1,N25=""),"",VLOOKUP(N25,RMR!$A$73:$B$79,2,FALSE)) | CA25: =IF(BZ25="","",IF(AND(BZ25=1,BW25=1),1,IF(AND(BZ25=1,BW25=2),2,IF(AND(BZ25=2,BW25=1),3,IF(AND(BZ25=2,BW25=2),4,"error")))))
O26: =IF(BY26="","",VLOOKUP(BY26,RMR!$N$77:$Q$81,4,TRUE)) | P26: =IF(CA26="","",VLOOKUP(CA26,RMR!$N$77:$Q$81,4,TRUE)) | Q26: =IF(BY26="","",VLOOKUP(BY26,RMR!$N$77:$Q$81,3,TRUE)) | R26: =IF(CA26="","",VLOOKUP(CA26,RMR!$N$76:$Q$79,3,TRUE)) | BW26: =IF(H26="","error",VLOOKUP(H26,RMR!$N$73:$P$74,3,TRUE)) -> error | BX26: =IF(OR(M26=-1,M26=""),"",VLOOKUP(M26,RMR!$A$72:$B$79,2,FALSE)) | BY26: =IF(BX26=3,5,IF(BX26="","",IF(AND(BX26=1,BW26=1),1,IF(AND(BX26=1,BW26=2),2,IF(AND(BX26=2,BW26=1),3,IF(AND(BX26=2,BW26=2),4,"error")))))) | BZ26: =IF(OR(N26=-1,N26=""),"",VLOOKUP(N26,RMR!$A$73:$B$79,2,FALSE)) | CA26: =IF(BZ26="","",IF(AND(BZ26=1,BW26=1),1,IF(AND(BZ26=1,BW26=2),2,IF(AND(BZ26=2,BW26=1),3,IF(AND(BZ26=2,BW26=2),4,"error")))))
O27: =IF(BY27="","",VLOOKUP(BY27,RMR!$N$77:$Q$81,4,TRUE)) | P27: =IF(CA27="","",VLOOKUP(CA27,RMR!$N$77:$Q$81,4,TRUE)) | Q27: =IF(BY27="","",VLOOKUP(BY27,RMR!$N$77:$Q$81,3,TRUE)) | R27: =IF(CA27="","",VLOOKUP(CA27,RMR!$N$76:$Q$79,3,TRUE)) | BW27: =IF(H27="","error",VLOOKUP(H27,RMR!$N$73:$P$74,3,TRUE)) -> error | BX27: =IF(OR(M27=-1,M27=""),"",VLOOKUP(M27,RMR!$A$72:$B$79,2,FALSE)) | BY27: =IF(BX27=3,5,IF(BX27="","",IF(AND(BX27=1,BW27=1),1,IF(AND(BX27=1,BW27=2),2,IF(AND(BX27=2,BW27=1),3,IF(AND(BX27=2,BW27=2),4,"error")))))) | BZ27: =IF(OR(N27=-1,N27=""),"",VLOOKUP(N27,RMR!$A$73:$B$79,2,FALSE)) | CA27: =IF(BZ27="","",IF(AND(BZ27=1,BW27=1),1,IF(AND(BZ27=1,BW27=2),2,IF(AND(BZ27=2,BW27=1),3,IF(AND(BZ27=2,BW27=2),4,"error")))))
O28: =IF(BY28="","",VLOOKUP(BY28,RMR!$N$77:$Q$81,4,TRUE)) | P28: =IF(CA28="","",VLOOKUP(CA28,RMR!$N$77:$Q$81,4,TRUE)) | Q28: =IF(BY28="","",VLOOKUP(BY28,RMR!$N$77:$Q$81,3,TRUE)) | R28: =IF(CA28="","",VLOOKUP(CA28,RMR!$N$76:$Q$79,3,TRUE)) | BW28: =IF(H28="","error",VLOOKUP(H28,RMR!$N$73:$P$74,3,TRUE)) -> error | BX28: =IF(OR(M28=-1,M28=""),"",VLOOKUP(M28,RMR!$A$72:$B$79,2,FALSE)) | BY28: =IF(BX28=3,5,IF(BX28="","",IF(AND(BX28=1,BW28=1),1,IF(AND(BX28=1,BW28=2),2,IF(AND(BX28=2,BW28=1),3,IF(AND(BX28=2,BW28=2),4,"error")))))) | BZ28: =IF(OR(N28=-1,N28=""),"",VLOOKUP(N28,RMR!$A$73:$B$79,2,FALSE)) | CA28: =IF(BZ28="","",IF(AND(BZ28=1,BW28=1),1,IF(AND(BZ28=1,BW28=2),2,IF(AND(BZ28=2,BW28=1),3,IF(AND(BZ28=2,BW28=2),4,"error")))))
H29: PROM 1 | J29: =AVERAGE(J15:J17) -> #DIV/0!
H30: PROM 2 | J30: =AVERAGE(J18:J20) -> #DIV/0!
H31: PROM 3 | J31: =AVERAGE(J21:J23) -> #DIV/0! | M31: JV: | N31: =((1/J29)+(1/J30)+(1/J31)) -> #DIV/0!

Sheet BD
A1: id | C1: CELDA | D1: CELDA | F1: ESTE_FROM | G1: NORTE_FROM | H1: COTA | J1: ESTE_TO | K1: NORTE_TO | L1: COTA | M1: Dist.Celda | N1: Altura | P1: DIP | R1: AZ_HOLE | T1: DIP_TALUD | V1: DIP DIR_TALUD | W1: INTEMPERISMO | Y1: CONDICION DE AGUA '76. | Z1: CONDICION DE AGUA VALOR '76 | AA1: DUREZA '76 | AB1: RESISTENCIA ESTIMADA VALOR '76 | AC1: GSI VISUAL '76 | AD1: CONTROL ESTRUCTURAL '76 | AE1: EFECTOS DE VOLADURA '76 | AF1: RQD - VALOR '76 | AG1: RQD '76 | AH1: FRECUENCIA DE FRACTURAMIENTO x m. '76 | AI1: TAMAÑO DE BLOQUES x m3 '76 | AJ1: ESPACIAMIENTO PROMEDIO '76 | AK1: ESPACIAMIENTO - VALOR '76 | AL1: CONDICIÓN DE DISCONTINUIDAD - VALOR '76 | AM1: RMR '76 | AN1: ( UCS ) (Mpa) | AO1: is50 (Mpa) | AQ1: CONDICION DE AGUA '89 | AR1: CONDICION DE AGUA VALOR '89 | AS1: DUREZA '89 | AT1: RESISTENCIA ESTIMADA VALOR '89 | AU1: GSI VISUAL '89 | AV1: CONTROL ESTRUCTURAL '89 | AW1: EFECTOS DE VOLADURA '89 | AX1: RQD - VALOR '89 | AY1: RQD '89 | AZ1: FRECUENCIA DE FRACTURAMIENTO x m. '89 | BA1: TAMAÑO DE BLOQUES x m3 '89 | BB1: ESPACIAMIENTO PROMEDIO '89 | BC1: ESPACIAMIENTO - VALOR '89 | BD1: CONDICIÓN DE DISCONTINUIDAD - VALOR '89 | BE1: RMR '89 | BG1: FECHA | BI1: COMENTARIO | BK1: Dist. de estr. | BL1: teta | BM1: alfa | BN1: x | BO1: y | BP1: z | BQ1: TIPO DE ESTRUCTURA | BR1: DIP | BS1: DIP DIR | BT1: NUMERO DE ESTRUCTURAS | BU1: ABERTURA mm. | BV1: ESPESOR mm. | BW1: CONTINUIDAD m. | BX1: ESPACIAMIENTO m. | BY1: NUMERO DE EXTREMOS VISIBLES | BZ1: TIPO DE RELLENO 1 | CA1: TIPO DE RELLENO 2 | CB1: JRC | CC1: RUGOSIDAD DE ESTRUCTURAS | CD1: FORMA DE ESTRUCTURA | CE1: ALTERACION | CG1: GEOTECNICO | CI1: Is50_Mpa | CK1: LITO3_MODELO | CM1: LITO-3 | CO1: Sector | CQ1: Nivel

Sheet RMR
A1: Valoraciones para el cálculo del RMR76 y RMR89
A4: Resistencia | B4: MPa | C4: rating 89* | D4: rating 76 | G4: Resistencia ISRM
A5: R6 | B5: > 250 | C5: 15 | D5: 15 | G5: UCS min (MPa) | H5: Abreviatura | I5: Denominación ISRM
A6: R5 | B6: 100 - 250 | C6: 12 | D6: 12 | G6: 0.25 | H6: R0 | I6: Extremadamente débil
A7: R4 | B7: 50 - 100 | C7: 7 | D7: 7 | G7: 1 | H7: R1 | I7: Muy débil
A8: R3 | B8: 25 - 50 | C8: 4 | D8: 4 | G8: 5 | H8: R2 | I8: Débil
A9: R2 | B9: 5 - 25 | C9: 2 | D9: 2 | G9: 25 | H9: R3 | I9: Moderadamente resistente
A10: R1 | B10: 1 - 5 | C10: 1 | D10: 1 | G10: 50 | H10: R4 | I10: Resistente
A11: R0 | B11: < 1 | C11: 0 | D11: 0 | G11: 100 | H11: R5 | I11: Muy resistente
A12: *SRK utilizará las curvas exponenciales de Bieniawaski(1989) | G12: 250 | H12: R6 | I12: Extremadamente resistente
A14: RQD (%) | C14: rating 89 | D14: rating 76
A15: 0 | B15: <25 | C15: 3 | D15: 3
A16: 25 | B16: 25-50 | C16: 8 | D16: 8
A17: 50 | B17: 50-75 | C17: 13 | D17: 13
A18: 75 | B18: 75-90 | C18: 17 | D18: 17
A19: 90 | B19: 90-100 | C19: 20 | D19: 20
A20: *SRK utilizará las curvas exponenciales de Bieniawaski(1989)
A22: ESPACIAMIENTO (m) | C22: rating 89 | D22: ESPACIAMIENTO (m) | F22: rating 76
A23: 0 | B23: <0.06 | C23: 5 | D23: 0 | E23: <0.05 | F23: 5
A24: 0.06 | B24: 0.06-0.2 | C24: 8 | D24: 0.05 | E24: 0.05-0.3 | F24: 10
A25: 0.2 | B25: 0.2-0.6 | C25: 10 | D25: 0.3 | E25: 0.3-1 | F25: 20
A26: 0.6 | B26: 0.6-2 | C26: 15 | D26: 1 | E26: 1-3 | F26: 25
A27: 2 | B27: >2 | C27: 20 | D27: 3 | E27: >3 | F27: 30
A28: *SRK utilizará las curvas exponenciales de Bieniawaski(1989)
A30: Continuidad | C30: rating 89 | D30: rating 76
A31: 1e-05 | B31: <1 m | C31: 6 | D31: 5
A32: 1 | B32: 1-3 m | C32: 4 | D32: 4
A33: 3 | B33: 3-10 m | C33: 2 | D33: 3
A34: 10 | B34: 10-20 m | C34: 1 | D34: 1
A35: 20 | B35: >20 m | C35: 0 | D35: 0
A39: Meteorización | B39: rating 89 | C39: rating 76
A40: f | B40: 6 | C40: 5
A41: d | B41: 5 | C41: 5
A42: m | B42: 3 | C42: 4
A43: a | B43: 3 | C43: 3
A44: c | B44: 2 | C44: 2
A45: s | B45: 1 | C45: 1
A46: *SRK modificó la valoracion
A50: Abertura | C50: Abertura (mm) | D50: rating 89 | E50: rating 76
A51: Masiva | B51: 0 | C51: 0 | D51: 6 | E51: 5
...

Sheet Leyenda
A1: Tipo de ensayo | D1: Diámetro de perforación | G1: Factor de corrección para ensayos de carga puntual ( 2020) | K1: Factor de correlación para ensayos de carga puntual (, 2023)
A2: Abreviatura | B2: Tipo de ensayo PLT | D2: Nominación | E2: Diámetro nominal (mm) | G2: Unidades geotécnicas | H2: Litología | I2: Factor de correlación (K) | L2: Litología 1 | M2: Litología 2 | N2: Litología 3 | O2: Factor K | Q2: Unidades geotécnicas | R2: Lito 2 | S2: Lito 3 | T2: Validacion Lito | U2: K
A3: D | B3: Diametral | D3: BQ | E3: 36.5 | G3: CARBONATOS | H3: LMT | I3: 15 | K3: INTRUSIVOS | L3: MZB | M3: MZB | N3: MZB_EQ | O3: 8.29 | Q3: INTRUSIVOS | R3: MZB | S3: MZB_EQ | T3: =CONCATENATE(R3,"/",S3) -> MZB/MZB_EQ | U3: 8.29 | V3: INTRUSIVOS
A4: A | B4: Axial | D4: NQ | E4: 47.6 | H4: MBC | I4: 19.7 | L4: MZB | M4: MZB | N4: MZB_P | O4: 8.53 | R4: MZB | S4: MZB_P | T4: =CONCATENATE(R4,"/",S4) -> MZB/MZB_P | U4: 8.53 | V4: INTRUSIVOS
A5: B | B5: Bloques | D5: HQ | E5: 61.1 | H5: MBL | I5: 18.7 | L5: MBF1 | M5: MBF | N5: MBF1 | O5: 9.2 | R5: MBF | S5: MBF1 | T5: =CONCATENATE(R5,"/",S5) -> MBF/MBF1 | U5: 9.2 | V5: INTRUSIVOS
A6: I | B6: Irregular | D6: PQ | E6: 85 | G6: INTRUSIVOS | H6: MZM | I6: 18.6 | L6: MBF2 | M6: MBF | N6: MBF2 | O6: 10.73 | R6: MBF | S6: MBF2 | T6: =CONCATENATE(R6,"/",S6) -> MBF/MBF2 | U6: 10.73 | V6: INTRUSIVOS
H7: MZB | I7: 16.8 | L7: MBF2 | M7: MBF | N7: MBF_P | O7: 9.31 | R7: MBF | S7: MBF_P | T7: =CONCATENATE(R7,"/",S7) -> MBF/MBF_P | U7: 9.31 | V7: INTRUSIVOS
H8: MBF | I8: 17.4 | L8: MZM | M8: MZM | N8: MZM_F | O8: 9.31 | R8: MZM | S8: MZM_F | T8: =CONCATENATE(R8,"/",S8) -> MZM/MZM_F | U8: 9.31 | V8: INTRUSIVOS
A9: Resistencia ISRM | H9: MBF1 | I9: 17.4 | L9: MZM | M9: MZM | N9: MZM_M | O9: 8.61 | R9: MZM | S9: MZM_M | T9: =CONCATENATE(R9,"/",S9) -> MZM/MZM_M | U9: 8.61 | V9: INTRUSIVOS
A10: UCS min (MPa) | B10: Abreviatura | C10: Denominación ISRM | H10: MBF2 | I10: 17.4 | L10: MZH | M10: MZH | N10: MZH_1 | O10: 11.62 | R10: MZH | S10: MZH_1 | T10: =CONCATENATE(R10,"/",S10) -> MZH/MZH_1 | U10: 11.62 | V10: INTRUSIVOS
A11: 0.25 | B11: R0 | C11: Extremadamente débil | H11: MZQ | I11: 18.1 | L11: MZH | M11: MZH | N11: MZH_2 | O11: 9.31 | R11: MZH | S11: MZH_2 | T11: =CONCATENATE(R11,"/",S11) -> MZH/MZH_2 | U11: 9.31 | V11: INTRUSIVOS
A12: 1 | B12: R1 | C12: Muy débil | H12: MZH | I12: 18.2 | L12: MZD | M12: MZD | N12: MZD | O12: 7.6 | R12: MZD | S12: MZD | T12: =CONCATENATE(R12,"/",S12) -> MZD/MZD | U12: 7.6 | V12: INTRUSIVOS
A13: 5 | B13: R2 | C13: Débil | G13: SKARN | H13: GSK | I13: 15.2 | L13: MZQ | M13: MZQ | N13: MZQ | O13: 12.29 | R13: MZQ | S13: MZQ | T13: =CONCATENATE(R13,"/",S13) -> MZQ/MZQ | U13: 12.29 | V13: INTRUSIVOS
A14: 25 | B14: R3 | C14: Moderadamente resistente | H14: PSK | I14: 15.1 | L14: AN | M14: AN | N14: LAM | O14: 9.31 | R14: MBF | S14: NR | T14: =CONCATENATE(R14,"/",S14) -> MBF/NR | U14: 9.31 | V14: INTRUSIVOS
A15: 50 | B15: R4 | C15: Resistente | H15: ESK | I15: 15.3 | K15: SEDIMENTARIOS | L15: LMT | M15: LMT | N15: LMT_M | O15: 14.74 | R15: MZM | S15: NR | T15: =CONCATENATE(R15,"/",S15) -> MZM/NR | U15: 9.31 | V15: INTRUSIVOS
A16: 100 | B16: R5 | C16: Muy resistente | H16: MSK | I16: 15.3 | L16: LMT | M16: LMT | N16: LMT_Mg | O16: 14.25 | R16: MZB | S16: NR | T16: =CONCATENATE(R16,"/",S16) -> MZB/NR | U16: 9.31 | V16: INTRUSIVOS
A17: 250 | B17: R6 | C17: Extremadamente resistente | G17: TODOS | H17: EGT | I17: 19.3 | L17: LMT | M17: LMT | N17: LMT_S | O17: 14.84 | R17: MZH | S17: NR | T17: =CONCATENATE(R17,"/",S17) -> MZH/NR | U17: 9.31 | V17: INTRUSIVOS
H18: EPG | I18: 18.3 | L18: LMT | M18: LMT | N18: LMT_C | O18: 16.83 | Q18: ENDOSKARN | R18: EGT | S18: MZM_M | T18: =CONCATENATE(R18,"/",S18) -> EGT/MZM_M | U18: 9.87 | V18: ENDOSKARN
H19: OTRO | I19: 17.7 | L19: LMT | M19: LMT | N19: LMT_U | O19: 14.84 | R19: EGT | S19: MZB_EQ | T19: =CONCATENATE(R19,"/",S19) -> EGT/MZB_EQ | U19: 9.87 | V19: ENDOSKARN
A20: Dirección de rotura | L20: SHL | M20: HFL | N20: SHL_MA | O20: 14.84 | R20: EGT | S20: - | T20: =CONCATENATE(R20,"/",S20) -> EGT/- | U20: 9.87 | V20: ENDOSKARN
A21: Pa | B21: Paralela a los planos de debilidad (estratificación, foliación) | K21: METAMORFICAS | L21: LMT | M21: GSK | N21: Varios | O21: 11.15 | R21: EPG | S21: MZB_EQ | T21: =CONCATENATE(R21,"/",S21) -> EPG/MZB_EQ | U21: 9.87 | V21: ENDOSKARN
A22: Pe | B22: Perpendicular a los planos de debilidad (estratificación, foliación) | L22: LMT | M22: PSK | N22: Varios | O22: 12.63 | R22: EPG | S22: MZM_M | T22: =CONCATENATE(R22,"/",S22) -> EPG/MZM_M | U22: 9.87 | V22: ENDOSKARN
A23: NA | B23: No aplica (rocas masivas sin planos de debilidad) | L23: LMT | M23: MSK | N23: Varios | O23: 12.63 | R23: EPG | S23: MZD | T23: =CONCATENATE(R23,"/",S23) -> EPG/MZD | U23: 9.87 | V23: ENDOSKARN
L24: LMT | M24: ESK | N24: Varios | O24: 12.63 | R24: EPG | S24: - | T24: =CONCATENATE(R24,"/",S24) -> EPG/- | U24: 9.87 | V24: ENDOSKARN
A25: Tipo de fractura | L25: LMT | M25: MBC | N25: Varios | O25: 11.78 | Q25: BRECHAS | R25: TBX | S25: TBX | T25: =CONCATENATE(R25,"/",S25) -> TBX/TBX | U25: 13.72 | V25: BRECHAS
A26: M | B26: Rotura por matriz. Si la muestra no se rompe se considera M. | L26: LMT | M26: MBL | N26: Varios | O26: 13.34 | R26: BX | S26: TBX | T26: =CONCATENATE(R26,"/",S26) -> BX/TBX | U26: 13.72 | V26: BRECHAS
A27: E | B27: Rotura por estructura | L27: SHL | M27: HFL | N27: - | O27: 12.63 | R27: HBX | S27: HBX | T27: =CONCATENATE(R27,"/",S27) -> HBX/HBX | U27: 11.41 | V27: BRECHAS
A28: C | B28: Rotura combinada, por matriz y estructura | L28: SND | M28: QZT | N28: - | O28: 12.63 | R28: MBX | S28: MBX | T28: =CONCATENATE(R28,"/",S28) -> MBX/MBX | U28: 11.41 | V28: BRECHAS
K29: BRECHAS | L29: TBX | M29: TBX | N29: TBX | O29: 13.72 | Q29: SEDIMENTARIAS | R29: LMT | S29: LMT | T29: =CONCATENATE(R29,"/",S29) -> LMT/LMT | U29: 14.84 | V29: SEDIMENTARIAS
L30: HBX | M30: HBX | N30: HBX | O30: 11.41 | R30: LMT | S30: NR | T30: =CONCATENATE(R30,"/",S30) -> LMT/NR | U30: 14.84 | V30: SEDIMENTARIAS
L31: MBX / varios | M31: MBX | N31: MBX | O31: 11.41 | R31: LMT | S31: LMT_M | T31: =CONCATENATE(R31,"/",S31) -> LMT/LMT_M | U31: 14.74 | V31: SEDIMENTARIAS
K32: ENDOSKARN | L32: Intrusivo | M32: EPG | N32: - | O32: 9.87 | R32: LMT | S32: LMT_MG | T32: =CONCATENATE(R32,"/",S32) -> LMT/LMT_MG | U32: 14.25 | V32: SEDIMENTARIAS
L33: Intrusivo | M33: EGT | N33: - | O33: 9.87 | R33: LMT | S33: LMT_S | T33: =CONCATENATE(R33,"/",S33) -> LMT/LMT_S | U33: 14.84 | V33: SEDIMENTARIAS
R34: LMT | S34: LMT_C | T34: =CONCATENATE(R34,"/",S34) -> LMT/LMT_C | U34: 16.83 | V34: SEDIMENTARIAS
K35: Nota: | R35: HFL | S35: SHL_MA | T35: =CONCATENATE(R35,"/",S35) -> HFL/SHL_MA | U35: 14.84 | V35: SEDIMENTARIAS
K36: Si se registra NR como litología 1, 2 o 3 en los ensayos de carga puntual | R36: OVD | S36: OVD | T36: =CONCATENATE(R36,"/",S36) -> OVD/OVD | U36: 14.84 | V36: SEDIMENTARIAS
K37: indica que la información no fue registrada al momento de registrar la muestra. | R37: OVD | S37: - | T37: =CONCATENATE(R37,"/",S37) -> OVD/- | U37: 14.84 | V37: SEDIMENTARIAS
Q38: METAMORFICAS | R38: GSK | S38: LMT_M | T38: =CONCATENATE(R38,"/",S38) -> GSK/LMT_M | U38: 11.15 | V38: METAMORFICAS
R39: GSK | S39: LMT_C | T39: =CONCATENATE(R39,"/",S39) -> GSK/LMT_C | U39: 11.15 | V39: METAMORFICAS
R40: GSK | S40: LMT_S | T40: =CONCATENATE(R40,"/",S40) -> GSK/LMT_S | U40: 11.15 | V40: METAMORFICAS
...
